Workbook

Sheet الملخص
B2: لوحة ملخص المخزون والاستلام
B3: آخر تحليل للصلاحية: 06.07.2026 — الإحصائيات في الجدول الأول تتحدّث تلقائياً مع تعديل البيانات
B5: إحصائيات الأوراق (تلقائية التحديث)
B6: الورقة | C6: عدد الدفعات | D6: دفعات برصيد حالي | E6: دفعات برصيد سالب (خطأ) | F6: ملاحظة
B7: RM & PM | C7: =COUNTA('RM & PM'!E2:E792) | D7: =COUNTIF('RM & PM'!AA2:AA792,">0") | E7: =COUNTIF('RM & PM'!AA2:AA792,"<-0.001") | F7: المواد الخام ومواد التعبئة الحالية
B8: Off -Records | C8: =COUNTA('Off -Records'!E2:E109) | D8: =COUNTIF('Off -Records'!W2:W109,">0") | E8: =COUNTIF('Off -Records'!W2:W109,"<-0.001") | F8: أصناف خارج السجلات الرسمية
B9: Inner & Assembled | C9: =COUNTA('Inner & Assembled'!D2:D833) | D9: =COUNTIF('Inner & Assembled'!O2:O833,">0") | E9: =COUNTIF('Inner & Assembled'!O2:O833,"<-0.001") | F9: المنتجات الداخلية والمجمّعة الحالية
B10: Stagnant I & A | C10: =COUNTA('Stagnant I & A'!D2:D928) | D10: =COUNTIF('Stagnant I & A'!O2:O928,">0") | E10: =COUNTIF('Stagnant I & A'!O2:O928,"<-0.001") | F10: أصناف راكدة
B11: Historical R&PM | C11: =COUNTA('Historical R&PM'!E2:E804) | D11: =COUNTIF('Historical R&PM'!AA2:AA804,">0") | E11: =COUNTIF('Historical R&PM'!AA2:AA804,"<-0.001") | F11: أرشيف المواد الخام والتعبئة
B12: Historical I & A | C12: =COUNTA('Historical I & A'!D2:D942) | D12: =COUNTIF('Historical I & A'!O2:O942,">0") | E12: =COUNTIF('Historical I & A'!O2:O942,"<-0.001") | F12: أرشيف المنتجات الداخلية والمجمّعة
B14: تنبيهات الصلاحية — أصناف برصيد حالي منتهية أو تنتهي خلال 180 يوم (لقطة بتاريخ 06.07.2026)
B15: الورقة | C15: الكود | D15: اسم الصنف | E15: رقم التشغيلة/الكنترول | F15: تاريخ الانتهاء | G15: الرصيد الحالي | H15: الحالة
B16: RM & PM | C16: PP0066 | D16: Alu Foil unprinted 30 micron thickness 196 mm width | E16: PP2400046 | F16: 31.10.2025 | G16: 145 | H16: منتهي الصلاحية
B17: RM & PM | C17: PP0065 | D17: Alu Foil unprinted 30 micron thickness 194 mm width | E17: PP2400053 | F17: 31.10.2025 | G17: 19.59 | H17: منتهي الصلاحية
B18: RM & PM | C18: SP0130 | D18: Box-Epasterin Soft Gelatin Capsule | E18: SP2400058 | F18: 03.04.2026 | G18: 3934 | H18: منتهي الصلاحية
B19: RM & PM | C19: SP0163 | D19: Pamphlet-Mega-Q Soft Gelatin Capsule | E19: SP2400055 | F19: 30.04.2026 | G19: 5129 | H19: منتهي الصلاحية
B20: RM & PM | C20: RM0035 | D20: Colloidal Silicon Dioxide | E20: RM2400030 | F20: 30.04.2026 | G20: 7.187 | H20: منتهي الصلاحية
B21: RM & PM | C21: RM0050 | D21: Copper Citrate | E21: RM2400026 | F21: 04.05.2026 | G21: 0.828 | H21: منتهي الصلاحية
B22: RM & PM | C22: SP0162 | D22: Box-Mega-Q Soft Gelatin Capsule | E22: SP2400054 | F22: 06.05.2026 | G22: 4770 | H22: منتهي الصلاحية
B23: RM & PM | C23: RM0013 | D23: Lactose Monohydrate | E23: RM2400020 | F23: 31.05.2026 | G23: 23.822 | H23: منتهي الصلاحية
B24: RM & PM | C24: SP0134 | D24: Polyamide/Polyethylene 300 µm 420 mm width roll | E24: SP2500017 | F24: 25.06.2026 | G24: 17336.223 | H24: منتهي الصلاحية
B25: RM & PM | C25: SP0153 | D25: Box-Moral 60 soft gelatin capsule | E25: SP2400043 | F25: 01.07.2026 | G25: 14571 | H25: منتهي الصلاحية
B26: Inner & Assembled | C26: PP0050 | D26: Assembled outer tube (155*23mm) tinted | E26: 25IPP036 | F26: 01.07.2026 | G26: 11689 | H26: منتهي الصلاحية
B27: RM & PM | C27: PP0025 | D27: Aluminum Seal Disc PE-Coat -D: 24mm | E27: PP2500028 | F27: 27.07.2026 | G27: 24008 | H27: ينتهي خلال 21 يوم
... B69: Inner & Assembled | C69: PP0038 | D69: Assembled Outer Tube 128*18mm clear | E69: 25IPP029 | F69: 01.01.2027 | G69: 6096 | H69: ينتهي خلال 179 يوم
B71: أرصدة سالبة تحتاج مراجعة (غالباً خطأ إدخال)
B72: الورقة | C72: الكود | D72: اسم الصنف | E72: الرصيد | F72: رقم الصف
B73: RM & PM | C73: PP0061 | D73: Alu Foil unprinted 30 micron thickness 240 mm width | E73: -0.03 | F73: 73
B74: RM & PM | C74: RM0032 | D74: Lactose Anhydrous | E74: -0.032 | F74: 255
B75: RM & PM | C75: BP0013 | D75: Povidone Iodine 7.5%-Bulk | E75: -0.2 | F75: 405
B76: RM & PM | C76: SP0226 | D76: Pamphlet-Prox-fem Sachet | E76: -10 | F76: 408
B77: RM & PM | C77: SP0220 | D77: Pamphlet-G1000 Sachet | E77: -10 | F77: 409
B78: RM & PM | C78: SP0224 | D78: Pamphlet-Ovemer Plus Sachet | E78: -10 | F78: 410
B79: RM & PM | C79: SP0227 | D79: Box-ProxFort Sachet | E79: -25 | F79: 411
B80: RM & PM | C80: SP0078 | D80: Pamphlet-Fertiovum Sachet | E80: -5 | F80: 412
B81: RM & PM | C81: SP0179 | D81: Box-Prime Ultra Sachet | E81: -25 | F81: 413
B82: RM & PM | C82: SP0077 | D82: Box-Fertiovum Sachet-30 Sachet | E82: -19 | F82: 414
B83: RM & PM | C83: SP0228 | D83: Pamphlet-ProxFort Sachet | E83: -10 | F83: 415
B84: RM & PM | C84: SP0082 | D84: Pamphlet-Inovari Puls Sachet-30 Sachet | E84: -10 | F84: 416
... B91: Inner & Assembled | C91: BP0067 | D91: FAS IODO Soln. 1% | E91: -0.06 | F91: 17

Sheet دليل الاستخدام
B2: دليل استخدام ملف الاستلام والمخزون
B4: ما الجديد في هذه النسخة؟
B5: 1. لوحة "الملخص": إحصائيات لكل ورقة + تنبيهات الأصناف المنتهية أو القريبة من انتهاء الصلاحية + الأرصدة السالبة.
B6: 2. أعمدة حركات الصرف (12 حركة × تاريخ/مستند/كمية) مجمّعة ومطوية افتراضياً — اضغط زر (+) أعلى يمين الأعمدة لعرضها، و(−) لإخفائها.
B7: 3. تجميد الصفوف والأعمدة: صف العناوين وأعمدة التعريف (حتى اسم الصنف) تبقى ظاهرة أثناء التمرير.
B8: 4. فلاتر تلقائية على كل الأعمدة: اضغط السهم في رأس أي عمود للتصفية أو الترتيب.
B9: 5. ترقيم حركات الصرف: Date (1), Doc No. (1), Qty (1) ... بدل التكرار بدون تمييز.
B10: 6. حذف آلاف الأعمدة الفارغة من ورقة Off -Records (كانت تبطئ الملف).
B12: دلالة ألوان رؤوس الأعمدة
B13: أزرق: بيانات تعريف الصنف (الكود، الاسم، المورد...) | أخضر مزرق: التواريخ | أخضر: الكميات المستلمة | برتقالي: أرصدة الحالة (المفرج عنه، الحجر، المرفوض) | رمادي: حركات الصرف.
B15: التنسيق الشرطي (يتحدّث تلقائياً)
B16: • الرصيد الحالي أحمر = رصيد سالب (خطأ إدخال يحتاج مراجعة).
... B27: RM & PM: استلامات المواد الخام ومواد التعبئة الحالية | Off -Records: أصناف خارج السجلات | Inner & Assembled: المنتجات الداخلية والمجمّعة | Stagnant I & A: الأصناف الراكدة | Historical R&PM و Historical I & A: الأرشيف.

Sheet RM & PM
A1: Item Category | B1: Rece. Date | C1: PO No. | D1: Doc. No. | E1: Code | F1: Description | G1: Cont. No. | H1: Manufacturer Name | I1: Supplier | J1: Supp. Lot No | K1: Mfg. Date | L1: MFG. D. | M1: Exp. Date | N1: EXP. D. | O1: Retest Date | P1: Sup. RET. D. | Q1: Int. RET. D. | R1: No. of packs | S1: Qty per packs | T1: Loose Pack | U1: Received Qty | V1: Unit | W1: Sample Qty | X1: Date | Y1: Remarks | Z1: Beg. Balance | AA1: Current released | AB1: Quarantine | AC1: Unrestricted | AD1: Restricted | AE1: Rejected | AF1: Date (1) | AG1: Doc No. (1) | AH1: Qty (1) | AI1: Date (2) | AJ1: Doc No. (2) | AK1: Qty (2) | AL1: Date (3) | AM1: Doc No. (3) | AN1: Qty (3) | AO1: Date (4) | AP1: Doc No. (4) | AQ1: Qty (4) | AR1: Date (5) | AS1: Doc No. (5) | AT1: Qty (5) | AU1: Date (6) | AV1: Doc No. (6) | AW1: Qty (6) | AX1: Date (7) | AY1: Doc No. (7) | AZ1: Qty (7) | BA1: Date (8) | BB1: Doc No. (8) | BC1: Qty (8) | BD1: Date (9) | BE1: Doc No. (9) | BF1: Qty (9) | BG1: Date (10) | BH1: Doc No. (10) | BI1: Qty (10) | BJ1: Date (11) | BK1: Doc No. (11) | BL1: Qty (11) | BM1: Date (12) | BN1: Doc No. (12) | BO1: Qty (12)
A2: SP | B2: 18/06/2023 | C2: SSMC0472023 | D2: 2300103 | E2: SP0062 | F2: BOPP Roll 20micron thickness 212mm width | G2: SP2300103 | H2: Al-Sharq Factories for Plastic | J2: 123122057 | K2: 11.06.2023 | L2: 11.06.2023 | M2: 11.06.2027 | N2: 11.06.2027 | O2: NA | P2: NA | Q2: 10.10.2026 | U2: 56 | V2: Kg. | Z2: =U2-W2 | AA2: =AC2+AH2+AK2+AN2+AQ2+AT2+AW2+AZ2+BC2+BF2+BI2+BL2+BO2 | AB2: 0 | AC2: =Z2-AD2-AE2-AB2 | AE2: 0
A3: SP | B3: 18/06/2023 | C3: SSMC0472023 | D3: 2300105 | E3: SP0064 | F3: BOPP Roll 20micron thickness 225mm width | G3: SP2300105 | H3: Al-Sharq Factories for Plastic | J3: 123122057 | K3: 11/06/2023 | L3: 11.06.2023 | M3: 11/06/2027 | N3: 11.06.2027 | O3: NA | P3: NA | Q3: 10.10.2026 | U3: 22.39 | V3: Kg. | Z3: =U3-W3 | AA3: =AC3+AH3+AK3+AN3+AQ3+AT3+AW3+AZ3+BC3+BF3+BI3+BL3+BO3 | AB3: 0 | AC3: =Z3-AD3-AE3-AB3 | AE3: 0
A4: SP | B4: 18/06/2023 | C4: SSMC0472023 | D4: 2300107 | E4: SP0066 | F4: BOPP Roll 20micron thickness 220mm width | G4: SP2300107 | H4: Al-Sharq Factories for Plastic | J4: 123122057 | K4: 11.06.2023 | L4: 11.06.2023 | M4: 11.06.2027 | N4: 11.06.2027 | O4: NA | P4: NA | Q4: 10.10.2026 | U4: 252.07 | V4: Kg. | Z4: =U4-W4 | AA4: =AC4+AH4+AK4+AN4+AQ4+AT4+AW4+AZ4+BC4+BF4+BI4+BL4+BO4 | AB4: 0 | AC4: =Z4-AD4-AE4-AB4 | AE4: 0 | AF4: 23.07.2025 | AG4: MR250102 | AH4: -99.6 | AI4: 03.09.2025 | AJ4: R-MR250102 | AK4: 25.685 | AL4: 15.09.2025 | AM4: MR250171 | AN4: -13.7 | AO4: 21.01.2026 | AP4: MR260011 | AQ4: -15.5 | AR4: 28.01.2026 | AS4: MR260017 | AT4: -12.43
A5: SP | B5: 18/06/2023 | C5: SSMC0472023 | D5: 2300108 | E5: SP0067 | F5: BOPP Roll 20micron thickness 172mm width | G5: SP2300108 | H5: Al-Sharq Factories for Plastic | J5: 123122057 | K5: 11.06.2023 | L5: 11.06.2023 | M5: 11.06.2027 | N5: 11.06.2027 | O5: NA | P5: NA | Q5: 10.10.2026 | U5: 162.724 | V5: Kg. | Z5: =U5-W5 | AA5: =AC5+AH5+AK5+AN5+AQ5+AT5+AW5+AZ5+BC5+BF5+BI5+BL5+BO5 | AB5: 0 | AC5: =Z5-AD5-AE5-AB5 | AE5: 0 | AF5: 29.06.2025 | AG5: MR250120 | AH5: -28.8 | AI5: 02.07.2025 | AJ5: R-LY627 | AK5: 3.58 | BP5: .
A6: SP | B6: 18/06/2023 | C6: SSMC0472023 | D6: 2300109 | E6: SP0068 | F6: BOPP Roll 20micron thickness 247mm width | G6: SP2300109 | H6: Al-Sharq Factories for Plastic | J6: 123122057 | K6: 11.06.2023 | L6: 11.06.2023 | M6: 11.06.2027 | N6: 11.06.2027 | O6: NA | P6: NA | Q6: 10.10.2026 | U6: 118.625 | V6: Kg. | Z6: =U6-W6 | AA6: =AC6+AH6+AK6+AN6+AQ6+AT6+AW6+AZ6+BC6+BF6+BI6+BL6+BO6 | AB6: 0 | AC6: =Z6-AD6-AE6-AB6 | AE6: 0 | AF6: 27.07.2025 | AG6: MR250141 | AH6: -56.16 | AI6: 03.09.2025 | AJ6: R-MR250141 | AK6: 24.26
A7: RM | B7: 45119 | C7: NA | D7: 2300114 | E7: RM0005 | F7: Empty Hard Gelatin Capsule size 0: Cap Colour Opaque Dark Green/S7.74 - Body Colour: Qpaque Light Green/S7.70 | G7: RM2300002 | H7: Saudi Gelatin and Capsule Co. | J7: HGC-RE230019 | K7: 03/2023 | L7: 00.03.2023 | M7: 03/2028 | N7: 00.03.2028 | O7: NA | P7: NA | U7: 61602 | V7: No. | Z7: =U7-W7 | AA7: =AC7+AH7+AK7+AN7+AQ7+AT7+AW7+AZ7+BC7+BF7+BI7+BL7+BO7 | AB7: 0 | AC7: =Z7-AD7-AE7-AB7 | AE7: 0
A8: RM | B8: 13/7/2023 | C8: NA | D8: 2300115 | E8: RM0006 | F8: Empty Hard Gelatin Capsule size 0: Cap Colour: Red - Body Colour: Red | G8: RM2300003 | H8: ACG Associated Capsules Private Limited | J8: 1100236695 | K8: 02/2023 | L8: 00.02.2023 | M8: 01/2028 | N8: 00.01.2028 | O8: NA | P8: NA | U8: 44000 | V8: No. | Z8: =U8-W8 | AA8: =AC8+AH8+AK8+AN8+AQ8+AT8+AW8+AZ8+BC8+BF8+BI8+BL8+BO8 | AB8: 0 | AC8: =Z8-AD8-AE8-AB8 | AE8: 0 | AF8: 12.06.2025 | AG8: MR250111 | AH8: -400
A9: RM | B9: 13/7/2023 | C9: NA | D9: 2300116 | E9: RM0007 | F9: Empty Hard Gelatin Capsule size 0: Cap Colour: White Opaque - Body Colour: White Opaque | G9: RM2300004 | H9: ACG Associated Capsules Private Limited | J9: 1150081822 | K9: 05/2023 | L9: 00.05.2023 | M9: 04/2028 | N9: 00.04.2028 | O9: NA | P9: NA | U9: 10000 | V9: No. | Z9: =U9-W9 | AA9: =AC9+AH9+AK9+AN9+AQ9+AT9+AW9+AZ9+BC9+BF9+BI9+BL9+BO9 | AB9: 10000 | AC9: =Z9-AD9-AE9-AB9 | AE9: 0
A10: RM | B10: 13/7/2023 | C10: NA | D10: 2300117 | E10: RM0007 | F10: Empty Hard Gelatin Capsule size 0: Cap Colour: White Opaque - Body Colour: White Opaque | G10: RM2300005 | H10: ACG Associated Capsules Private Limited | J10: 1150081823 | K10: 04/2023 | L10: 00.04.2023 | M10: 03/2028 | N10: 00.03.2028 | O10: NA | P10: NA | U10: 25000 | V10: No. | Z10: =U10-W10 | AA10: =AC10+AH10+AK10+AN10+AQ10+AT10+AW10+AZ10+BC10+BF10+BI10+BL10+BO10 | AB10: 25000 | AC10: =Z10-AD10-AE10-AB10 | AE10: 0
A11: RM | B11: 13/7/2023 | C11: NA | D11: 2300118 | E11: RM0008 | F11: Empty Hard Gelatin Capsule size 0: Cap Colour: Opaque Scarlet - Body Colour: Opaque Scarlet | G11: RM2300006 | H11: ACG Associated Capsules Private Limited | J11: 1150081824 | K11: 04/2023 | L11: 00.04.2023 | M11: 03/2028 | N11: 00.03.2028 | O11: NA | P11: NA | U11: 32000 | V11: No. | Z11: =U11-W11 | AA11: =AC11+AH11+AK11+AN11+AQ11+AT11+AW11+AZ11+BC11+BF11+BI11+BL11+BO11 | AB11: 32000 | AC11: =Z11-AD11-AE11-AB11 | AE11: 0
A12: RM | B12: 13/7/2023 | C12: NA | D12: 2300119 | E12: RM0009 | F12: Empty Hard Gelatin Capsule size 0: Cap Colour: Maroon Opaque - Body Colour: Maroon Opaque | G12: RM2300007 | H12: ACG Associated Capsules Private Limited | J12: 1150081825 | K12: 04/2023 | L12: 00.04.2023 | M12: 03/2028 | N12: 00.03.2028 | O12: NA | P12: NA | U12: 33000 | V12: No. | Z12: =U12-W12 | AA12: =AC12+AH12+AK12+AN12+AQ12+AT12+AW12+AZ12+BC12+BF12+BI12+BL12+BO12 | AB12: 33000 | AC12: =Z12-AD12-AE12-AB12 | AE12: 0
A13: RM | B13: 45146 | C13: SSMC0512023 | D13: 2300120 | E13: RM0010 | F13: Empty Hard Gelatin Capsule size 0: Cap Colour: Med. Orange Opaque C035 - Body Colour: Med. Orange Opaque C035 | G13: RM2300008 | H13: Capsugel Belgium NV | J13: 3651676 | K13: 18/06/2021 | L13: 18.06.2021 | M13: 18/06/2026 | N13: 18.06.2026 | O13: NA | P13: NA | U13: 194000 | V13: No. | Z13: =U13-W13 | AA13: =AC13+AH13+AK13+AN13+AQ13+AT13+AW13+AZ13+BC13+BF13+BI13+BL13+BO13 | AB13: 188000 | AC13: =Z13-AD13-AE13-AB13 | AE13: 0 | AF13: 03.02.2026 | AG13: MR260021 | AH13: -100000 | AI13: 08.02.2026 | AJ13: R-MR260021 | AK13: 94000
A14: SP | B14: 45148 | C14: NA | D14: 2300125 | E14: SP0060 | F14: Box-Blank [130mm X 542mm X 86mm] | G14: SP2300113 | H14: NA | J14: NA | K14: NA | L14: NA | M14: NA | N14: NA | O14: NA | P14: NA | U14: 2180 | V14: No. | Y14: Trials | Z14: =U14-W14 | AA14: =AC14+AH14+AK14+AN14+AQ14+AT14+AW14+AZ14+BC14+BF14+BI14+BL14+BO14 | AB14: 0 | AC14: =Z14-AD14-AE14-AB14 | AD14: 2180 | AE14: 0
A15: SP | B15: 45148 | C15: NA | D15: 2300126 | E15: SP0061 | F15: Pamphlet Blank | G15: SP2300114 | H15: NA | J15: NA | K15: NA | L15: NA | M15: NA | N15: NA | O15: NA | P15: NA | U15: 233 | V15: No. | Y15: Trials | Z15: =U15-W15 | AA15: =AC15+AH15+AK15+AN15+AQ15+AT15+AW15+AZ15+BC15+BF15+BI15+BL15+BO15 | AB15: 0 | AC15: =Z15-AD15-AE15-AB15 | AD15: 233 | AE15: 0
A16: SP | B16: 16/8/2023 | C16: NA | D16: 2300130 | E16: SP0072 | F16: Box Blank [W 6.5 X L 6.5 X H 11.5cm] | G16: SP2300116 | H16: NA | J16: NA | K16: NA | L16: NA | M16: NA | N16: NA | O16: NA | P16: NA | U16: 22450 | V16: No. | Y16: Trials | Z16: =U16-W16 | AA16: =AC16+AH16+AK16+AN16+AQ16+AT16+AW16+AZ16+BC16+BF16+BI16+BL16+BO16 | AB16: 0 | AC16: =Z16-AD16-AE16-AB16 | AD16: 22450 | AE16: 0
A17: RM | B17: 19/08/2023 | C17: SSMC0602023 | D17: 2300132 | E17: RM0012 | F17: Magnesium Stearate | G17: RM2300013 | H17: Peter Greven Nederland | J17: C250272 | K17: 11/2022 | L17: 00.11.2022 | M17: 11/2026 | N17: 00.11.2026 | O17: NA | P17: NA | Q17: 09.01.2027 | U17: 16.594 | V17: Kg. | Z17: =U17-W17 | AA17: =AC17+AH17+AK17+AN17+AQ17+AT17+AW17+AZ17+BC17+BF17+BI17+BL17+BO17 | AB17: 0 | AC17: =Z17-AD17-AE17-AB17 | AE17: 0 | AF17: 18.08.2025 | AG17: MR250153 | AH17: 0.1 | AI17: 15.09.2025 | AJ17: T25I001 | AK17: -0.683 | AL17: 15.09.2025 | AM17: T25I002 | AN17: -0.78 | AO17: 18.09.2025 | AP17: C25I001 | AQ17: -1.05 | AR17: 13.10.2025 | AS17: MR250194 | AT17: -0.05 | AU17: 23 2-26.10.2025 | AV17: T25J001 T25J002 T25J003 | AW17: =-3*(0.208) | AX17: 26.10.2025 | AY17: MR250209 | AZ17: -0.05 | BA17: 3-29.10.2025 | BB17: T25J004-5-6 | BC17: =-3*(0.208) | BD17: 10.11.2025 | BE17: C25K002 | BF17: -0.1569 | BG17: 10.11.2025 | BH17: C25K003 | BI17: =-(0.135) | BJ17: 05.02.2026 | BK17: C26B001 | BL17: -1.89
A18: RM | B18: 20/08/2023 | C18: NA | D18: 2300134 | E18: RM0014 | F18: Sucrose | G18: RM2300015 | H18: Durrah Advanced Development Co. | J18: 1230318L1 | K18: 03/2023 | L18: 00.03.2023 | M18: 03/2028 | N18: 00.03.2028 | O18: NA | P18: NA | U18: 9.46 | V18: Kg. | Z18: =U18-W18 | AA18: =AC18+AH18+AK18+AN18+AQ18+AT18+AW18+AZ18+BC18+BF18+BI18+BL18+BO18 | AB18: 0 | AC18: =Z18-AD18-AE18-AB18 | AE18: 0
A19: SP | B19: 45023 | C19: HTA-2023-001 | D19: 2300138 | E19: SP0070 | F19: Tear Tape 2.5mm width gold self adhesive | G19: SP2300118 | H19: Hainan Tianjian Anti-Forgery S&T Co., Ltd | J19: NA | K19: 07/2023 | L19: 00.07.2023 | M19: 07/2027 | N19: 00.07.2027 | O19: NA | P19: NA | Q19: 10.13.2026 | U19: 57 | V19: No. | Z19: =U19-W19 | AA19: =AC19+AH19+AK19+AN19+AQ19+AT19+AW19+AZ19+BC19+BF19+BI19+BL19+BO19 | AB19: 0 | AC19: =Z19-AD19-AE19-AB19 | AE19: 0 | AF19: 09.07.2025 | AG19: MR250104 | AH19: -1 | AI19: 16.07.2025 | AJ19: MR250132 | AK19: -6 | AL19: 17.07.2025 | AM19: MR250135 | AN19: -1 | AO19: 27.07.2025 | AP19: MR250141 | AQ19: -2 | AR19: 01.09.2025 | AS19: MR250163 | AT19: -4 | AU19: 19.11.2025 | AV19: MR250236 | AW19: -2 | AX19: 27.11.2025 | AY19: MR250245 | AZ19: -1 | BA19: 21.12.2025 | BB19: MR250268 | BC19: -1
A20: RM | B20: 15/10/2023 | C20: SSMC1042023 | D20: 2300141 | E20: RM0017 | F20: Maize Starch | G20: RM2300016 | H20: Roquette | J20: E3602 | K20: 20/11/2021 | L20: 20.11.2021 | M20: 20/11/2026 | N20: 20.11.2026 | O20: NA | P20: NA | U20: 6.728 | V20: Kg. | Z20: =U20-W20 | AA20: =AC20+AH20+AK20+AN20+AQ20+AT20+AW20+AZ20+BC20+BF20+BI20+BL20+BO20 | AB20: 0 | AC20: =Z20-AD20-AE20-AB20 | AE20: 0 | AF20: 18.08.2025 | AG20: MR250153 | AH20: -0.9 | AI20: 26.10.2025 | AJ20: MR250209 | AK20: -1
A21: RM | B21: 15/10/2023 | C21: SSMC1042023 | D21: 2300142 | E21: RM0018 | F21: Talc Powder | G21: RM2300017 | H21: Imerys Tlac Italy S.p.A | J21: S496/21 | K21: 13/07/2021 | L21: 13.07.2021 | M21: 07/2026 | N21: 12.07.2026 | O21: NA | P21: NA | U21: 23.633 | V21: Kg. | Z21: =U21-W21 | AA21: =AC21+AH21+AK21+AN21+AQ21+AT21+AW21+AZ21+BC21+BF21+BI21+BL21+BO21 | AB21: 0 | AC21: =Z21-AD21-AE21-AB21 | AE21: 0 | AF21: 15.09.2025 | AG21: T25I001 | AH21: -1.024 | AI21: 15.09.2025 | AJ21: T25I002 | AK21: -1.17
A22: RM | B22: 15/10/2023 | C22: NA | D22: 2300143 | E22: RM0019 | F22: Hydroxypropyl Methylcellulose-Methocel E5 Premium LV | G22: RM2300018 | H22: Dupont Nutrition & Bioscience (UK) Ltd | J22: 2444260442 | K22: 01/09/2022 | L22: 01.09.2022 | M22: NA | N22: NA | O22: 31/08/2027 | P22: 31.08.2027 | U22: 0.8 | V22: Kg. | Y22: Trials ? | Z22: =U22-W22 | AA22: =AC22+AH22+AK22+AN22+AQ22+AT22+AW22+AZ22+BC22+BF22+BI22+BL22+BO22 | AB22: 0 | AC22: =Z22-AD22-AE22-AB22 | AE22: 0
A23: PP | B23: 09.11.2023 | C23: NA | D23: 2300153 | E23: PP0012 | F23: Silver Aluminum/Polyethylene Seal Roll 150 µm 83 mm width | G23: PP2300008 | H23: NA | J23: NA | K23: NA | L23: NA | M23: NA | N23: NA | O23: NA | P23: NA | Q23: N.A | U23: 8.239 | V23: Kg. | Z23: =U23-W23 | AA23: =AC23+AH23+AK23+AN23+AQ23+AT23+AW23+AZ23+BC23+BF23+BI23+BL23+BO23 | AB23: 0 | AC23: =Z23-AD23-AE23-AB23 | AE23: 0
A24: SP | B24: 27/11/2023 | C24: NA | D24: 2300168 | E24: SP0104 | F24: Polypropylene/Polyethylene 300 µm 420 mm width roll | G24: SP2300123 | H24: STERIFIT Srl Società Unipersonale | J24: NA | K24: NA | L24: NA | M24: NA | N24: NA | O24: NA | P24: NA | Q24: N.A | U24: 80 | V24: Kg. | W24: 0.3 | Y24: Trials | Z24: =U24-W24 | AA24: =AC24+AH24+AK24+AN24+AQ24+AT24+AW24+AZ24+BC24+BF24+BI24+BL24+BO24 | AB24: 0 | AC24: =Z24-AD24-AE24-AB24 | AD24: 79.7 | AE24: 0 | BQ24: .
A25: SP | B25: 27/11/2023 | C25: NA | D25: 2300169 | E25: SP0105 | F25: Medical Paper 60gm-Blank 408 mm width | G25: SP2300124 | H25: STERIFIT Srl Società Unipersonale | J25: NA | K25: NA | L25: NA | M25: NA | N25: NA | O25: NA | P25: NA | Q25: N.A | U25: 6 | V25: Kg. | W25: 0.15 | Y25: Trials | Z25: =U25-W25 | AA25: =AC25+AH25+AK25+AN25+AQ25+AT25+AW25+AZ25+BC25+BF25+BI25+BL25+BO25 | AB25: 0 | AC25: =Z25-AD25-AE25-AB25 | AD25: 5.85 | AE25: 0 | BQ25: .
A26: Bu | B26: 12.04.2023 | C26: NA | D26: 2300170 | E26: BP0004 | F26: FAS Chlorex 2% Solution | G26: BP2300002 | H26: Giochemica S.R.L. | J26: O0900 | K26: 08/11/2023 | L26: 08.11.2023 | M26: 07/11/2026 | N26: 07.11.2026 | O26: NA | P26: NA | U26: 33.05 | V26: Kg. | Y26: Trial | Z26: =U26-W26 | AA26: =AC26+AH26+AK26+AN26+AQ26+AT26+AW26+AZ26+BC26+BF26+BI26+BL26+BO26 | AB26: 0 | AC26: =Z26-AD26-AE26-AB26 | AE26: 0 | AF26: 26.10.2025 | AG26: MR250210 | AH26: -33.05 | AI26: 27.10.2025 | AJ26: R-MR250210 | AK26: 32.4 | AN26: 0
A27: Bu | B27: 21.01.2024 | D27: 2400012 | E27: BP0006 | F27: FAS Chlorex 0.5% Solution | G27: BP2400001 | H27: Giochemica S.R.L. | J27: O1011 | K27: 12/2023 | L27: 00.12.2023 | M27: 12/2026 | N27: 00.12.2028 | O27: NA | P27: NA | U27: 266.15 | V27: Kg. | Z27: =U27-W27 | AA27: =AC27+AH27+AK27+AN27+AQ27+AT27+AW27+AZ27+BC27+BF27+BI27+BL27+BO27 | AB27: 0 | AC27: =Z27-AD27-AE27-AB27 | AE27: 0 | AF27: 26.06.2025 | AG27: 25IBP018 | AH27: -71.4 | AI27: 30.06.2025 | AJ27: 25IBP019 | AK27: -193.3 | AL27: 01.07.2025 | AM27: R-25IBP018 | AN27: 52.05 | AO27: 01.07.2025 | AP27: R-25IBP019 | AQ27: 138.75 | AR27: 20.10.2025 | AS27: 25IBP036 | AT27: -138.6 | AU27: 23.10.2025 | AV27: R-25IBP036 | AW27: 126.5
A28: SPM | B28: 21/01/2024 | C28: SSMC0472023 | D28: 2400015 | E28: SP0063 | F28: BOPP Roll 20micron thickness 195mm width | G28: SP2400004 | H28: Falcon Plastic Products Company | J28: NA | K28: 01/2024 | L28: 00.01.2024 | M28: 00.01.2026 | N28: 00.01.2026 | O28: NA | P28: NA | Q28: 10.01.2026 | U28: 112.266 | V28: Kg. | Y28: Exp. | Z28: 112.266 | AA28: =AC28+AH28+AK28+AN28+AQ28+AT28+AW28+AZ28+BC28+BF28+BI28+BL28+BO28 | AB28: 0 | AC28: =Z28-AD28-AE28-AB28 | AD28: 11.726 | AE28: 0 | AF28: 16.07.2025 | AG28: MR250132 | AH28: -112.27 | AI28: 03.09.2025 | AJ28: R-MR250132 | AK28: 11.73
A29: SP | B29: 21/01/2024 | C29: SSMC0472023 | D29: 2400016 | E29: SP0065 | F29: BOPP Roll 20micron thickness 203mm width | G29: SP2400005 | H29: Falcon Plastic Products Company | J29: NA | K29: 01/2024 | L29: 00.01.2024 | M29: 01/2026 | N29: 00.01.2026 | O29: NA | P29: NA | Q29: 10.01.2026 | U29: 424.472 | V29: Kg. | Y29: Exp. | Z29: =U29-W29 | AA29: =AC29+AH29+AK29+AN29+AQ29+AT29+AW29+AZ29+BC29+BF29+BI29+BL29+BO29 | AC29: =Z29-AD29-AE29-AB29 | AD29: 405.072 | AE29: 0 | AF29: 17.07.2025 | AG29: MR250135 | AH29: -49.9 | AI29: 03.09.2025 | AJ29: R-MR250135 | AK29: 30.5
A30: SP | B30: 25/01/2024 | C30: Euro-2023-001 | D30: 2400017 | E30: SP0087 | F30: Label-FAS Chlorex Sterile Solution 1% Clear-3ml [Size 6 cm x 5 cm] | G30: SP2400006 | H30: Eurolabel S.r.I | J30: 3342843339 | K30: 18/12/2023 | L30: 18.12.2023 | M30: 18/12/2025 | N30: 18.12.2025 | O30: NA | P30: NA | Q30: 04.02.2026 | U30: 950 | V30: No. | Y30: Exp. | Z30: =U30-W30 | AA30: =AC30+AH30+AK30+AN30+AQ30+AT30+AW30+AZ30+BC30+BF30+BI30+BL30+BO30 | AB30: 0 | AC30: =Z30-AD30-AE30-AB30 | AD30: 950 | AE30: 0
A31: SP | B31: 25/01/2024 | C31: Euro-2023-001 | D31: 2400018 | E31: SP0089 | F31: Label-FAS IODO Sterile Solution 10%-3ml [Size 6 cm x 5 cm] | G31: SP2400007 | H31: Eurolabel S.r.I | J31: 3342843341 | K31: 18/12/2023 | L31: 18.12.2023 | M31: 18/12/2025 | N31: 18.12.2025 | O31: NA | P31: NA | Q31: 04.02.2026 | U31: 3078 | V31: No. | Z31: =U31-W31 | AA31: =AC31+AH31+AK31+AN31+AQ31+AT31+AW31+AZ31+BC31+BF31+BI31+BL31+BO31 | AB31: 0 | AC31: =Z31-AD31-AE31-AB31 | AE31: 3078
A32: PP | B32: 45328 | C32: NA | D32: 2400027 | E32: PP0035 | F32: Regulator Disc [D 24/L 6mm] PP/PE fiber 0.08g/cm3-Applicator 26ml | G32: PP2400015 | H32: Porex Technologies Reinbek GmbH | J32: 001002-001003 | K32: 04/12/2023 | L32: 04.12.2023 | M32: 04/12/2025 | N32: 04.12.2025 | O32: NA | P32: NA | Q32: 12.02.2026 | U32: 41751 | V32: No. | Z32: =U32-W32 | AA32: =AC32+AH32+AK32+AN32+AQ32+AT32+AW32+AZ32+BC32+BF32+BI32+BL32+BO32 | AB32: 0 | AC32: =Z32-AD32-AE32-AB32 | AD32: 11751 | AE32: 0 | AF32: 07.09.2025 | AG32: 25IPP021 | AH32: -15000 | AI32: 17.09.2025 | AJ32: 25IPP023 | AK32: -15000
A33: SP | B33: 45330 | C33: Euro-2023-001 | D33: 2400035 | E33: SP0087 | F33: Label-FAS Chlorex Sterile Solution 1% Clear-3ml [Size 6 cm x 5 cm] | G33: SP2400013 | H33: Eurolabel S.r.I | J33: 3342843339 | K33: 18/12/2023 | L33: 18.12.2023 | M33: 18/12/2025 | N33: 18.12.2025 | O33: NA | P33: NA | Q33: 15.02.2026 | U33: 42988 | V33: No. | Y33: Exp. | Z33: =U33-W33 | AA33: =AC33+AH33+AK33+AN33+AQ33+AT33+AW33+AZ33+BC33+BF33+BI33+BL33+BO33 | AB33: 0 | AC33: =Z33-AD33-AE33-AB33 | AD33: 42988 | AE33: 0 | BP33: .
A34: SP | B34: 45330 | C34: Euro-2023-001 | D34: 2400036 | E34: SP0089 | F34: Label-FAS IODO Sterile Solution 10%-3ml [Size 6 cm x 5 cm] | G34: SP2400014 | H34: Eurolabel S.r.I | J34: 3342843341 | K34: 18/12/2023 | L34: 18.12.2023 | M34: 18/12/2025 | N34: 18.12.2025 | O34: NA | P34: NA | Q34: 15.02.2026 | U34: 44994 | V34: No. | Z34: =U34-W34 | AA34: =AC34+AH34+AK34+AN34+AQ34+AT34+AW34+AZ34+BC34+BF34+BI34+BL34+BO34 | AB34: 0 | AC34: =Z34-AD34-AE34-AB34 | AE34: 44994 | BP34: .
A35: SP | B35: 45330 | C35: Euro-2023-001 | D35: 2400038 | E35: SP0088 | F35: Label-FAS Chlorex Sterile Solution 0.5% Clear-3ml [Size 6 cm x 5 cm] | G35: SP2400016 | H35: Eurolabel S.r.I | J35: 3342843340 | K35: 18/12/2023 | L35: 18.12.2023 | M35: 18/12/2025 | N35: 18.12.2025 | O35: NA | P35: NA | Q35: 15.02.2026 | U35: 41099 | V35: No. | Y35: Exp. | Z35: =U35-W35 | AA35: =AC35+AH35+AK35+AN35+AQ35+AT35+AW35+AZ35+BC35+BF35+BI35+BL35+BO35 | AB35: 0 | AC35: =Z35-AD35-AE35-AB35 | AD35: 29641 | AE35: 0 | AF35: 30.06.2025 | AG35: L25F009 | AH35: -8000 | AI35: 06.07.2025 | AJ35: R-L25F009 | AK35: 1130 | AL35: 21.10.2025 | AM35: L25J009 | AN35: -5105 | AO35: 23.10.2025 | AP35: R-L25J009 | AQ35: 517
A36: RM | B36: 45334 | C36: NA | D36: 2400041 | E36: RM0027 | F36: Croscarmellose Sodium | G36: RM2400003 | H36: Dupont Nutrition ireland | J36: 4574468489 | K36: 09/08/2023 | L36: 09.08.2023 | M36: 07/08/2026 | N36: 07.08.2026 | O36: NA | P36: NA | Q36: 21.08.2027 | U36: 47.542 | V36: Kg. | Z36: =U36-W36 | AA36: =AC36+AH36+AK36+AN36+AQ36+AT36+AW36+AZ36+BC36+BF36+BI36+BL36+BO36 | AB36: 0 | AC36: =Z36-AD36-AE36-AB36 | AE36: 0 | AF36: 25.08.2025 | AG36: MR R&D | AH36: -0.2 | AI36: 23 2-26.10.2025 | AJ36: T25J001 T25J002 T25J003 | AK36: =-3*(1.03) | AL36: 3-29.10.2025 | AM36: T25J004-5-6 | AN36: =-(3*1.03) | AO36: 10.11.2025 | AP36: C25K002 | AQ36: -0.1419
A37: RM | B37: 45334 | C37: NA | D37: 2400042 | E37: RM0026 | F37: Microcrystalline Cellulose PH 112 | G37: RM2400004 | H37: Dupont Nutrition ireland | J37: 4574468367 | K37: 25/07/2023 | L37: 25.07.2023 | M37: 24/07/2027 | N37: 24.07.2027 | O37: NA | P37: NA | Q37: 12.03.2027 | U37: 40.79 | V37: Kg. | W37: 0.24 | Z37: =U37-W37 | AA37: =AC37+AH37+AK37+AN37+AQ37+AT37+AW37+AZ37+BC37+BF37+BI37+BL37+BO37 | AB37: 0 | AC37: =Z37-AD37-AE37-AB37 | AE37: 0
A38: PP | B38: 13/02/2024 | C38: NA | D38: 2400044 | E38: PP0041 | F38: Sponge with Plastic Scrub | G38: PP2400020 | H38: Jianerkang Medical Co.,Ltd. | J38: NA | K38: 28/12/2023 | L38: NA | M38: 01/01/2026 | N38: NA | O38: NA | P38: NA | U38: 2110 | V38: No. | Z38: =U38-W38 | AA38: =AC38+AH38+AK38+AN38+AQ38+AT38+AW38+AZ38+BC38+BF38+BI38+BL38+BO38 | AB38: 0 | AC38: =Z38-AD38-AE38-AB38 | AD38: 2110 | AE38: 0
A39: RM | B39: 25/02/2024 | C39: NA | D39: 2400049 | E39: RM0020 | F39: Hydroxypropyl Methylcellulose-Methocel E15 Premium LV | G39: RM2400005 | H39: Colorcon Limited | J39: 123120127 | K39: 29/01/2023 | L39: 29.01.2023 | M39: 03/01/2028 | N39: 03.01.2028 | O39: NA | P39: NA | U39: 17.225 | V39: Kg. | Z39: =U39-W39 | AA39: =AC39+AH39+AK39+AN39+AQ39+AT39+AW39+AZ39+BC39+BF39+BI39+BL39+BO39 | AB39: 0 | AC39: =Z39-AD39-AE39-AB39 | AE39: 0
A40: RM | B40: 25/02/2024 | C40: NA | D40: 2400050 | E40: RM0022 | F40: Opadry Pink Powder 03F540042 | G40: RM2400006 | H40: Colorcon Limited | J40: 123110048 | K40: 28/11/2023 | L40: 28.11.2023 | M40: 26/11/2026 | N40: 26.11.2026 | O40: NA | P40: NA | U40: 6.18 | V40: Kg. | Z40: =U40-W40 | AA40: =AC40+AH40+AK40+AN40+AQ40+AT40+AW40+AZ40+BC40+BF40+BI40+BL40+BO40 | AB40: 0 | AC40: =Z40-AD40-AE40-AB40 | AE40: 0
...

Sheet Off -Records
A1: Item Category | B1: Rece. Date | C1: PO No. | D1: Doc. No. | E1: Item Code | F1: Item Name | G1: Control No. | H1: Manufacturer Name | I1: Supplier | J1: Supp. Lot No | K1: Mfg. Date | L1: Exp. Date | M1: Retest Date | N1: No. of packs | O1: Qty per packs | P1: Loose Pack | Q1: Received Qty | R1: Unit | S1: Sample Qty | T1: Date | U1: Remarks | V1: Beg. Balance | W1: Current released | X1: Quarantine | Y1: Unrestricted | Z1: Restricted | AA1: Rejected | AB1: Date (1) | AC1: Doc No. (1) | AD1: Qty (1) | AE1: Date (2) | AF1: Doc No. (2) | AG1: Qty (2) | AH1: Date (3) | AI1: Doc No. (3) | AJ1: Qty (3) | AK1: Date (4) | AL1: Doc No. (4) | AM1: Qty (4) | AN1: Date (5) | AO1: Doc No. (5) | AP1: Qty (5) | AQ1: Date (6) | AR1: Doc No. (6) | AS1: Qty (6) | AT1: Date (7) | AU1: Doc No. (7) | AV1: Qty (7) | AW1: Date (8) | AX1: Doc No. (8) | AY1: Qty (8) | AZ1: Date (9) | BA1: Doc No. (9) | BB1: Qty (9) | BC1: Date (10) | BD1: Doc No. (10) | BE1: Qty (10) | BF1: Date (11) | BG1: Doc No. (11) | BH1: Qty (11) | BI1: Date (12) | BJ1: Doc No. (12) | BK1: Qty (12)
A2: Bulk | B2: 19.09.2024 | C2: NA | D2: 2400229 | E2: RM0041 | F2: Chlorhexidine Gluconate 20% Solution | G2: RM2400027 | H2: Basic Pharma Life Science Pvt. Ltd. | J2: 23BPLS/CHG090 | K2: 07/2023 | L2: 06/2026 | M2: NA | Q2: 98 | R2: Kg. | V2: 98 | W2: =Y2+AD2+AG2+AJ2+AM2+AP2 | X2: 0 | Y2: 98 | AA2: 0 | AC2: L25F006 | AD2: -26 | AE2: 28.07.2025 | AF2: L25G014 | AG2: -28.8 | AH2: 29.07.2025 | AI2: L25G015 | AJ2: -19.8 | AK2: 30.07.2025 | AL2: L25G016 | AM2: -19.8 | AN2: 17.09.2025 | AP2: -3.6
A3: Bulk | B3: 04.08.2025 | E3: RM0041 | F3: Chlorhexidine Gluconate 20% Solution | G3: N/A (S. lot No. CGN2024053) | H3: Alam Al-Saydalah | J3: CGN2024053 | K3: 05/2024 | L3: 05/2027 | M3: NA | Q3: 200 | R3: Kg. | U3: Assay 17.97%. | V3: =Q3-S3 | W3: =Y3+AD3+AG3+AJ3+AM3+AP3+AS3+AV3+AY3+BB3+BE3+BH3+BK3 | X3: 0 | Y3: =V3-X3-Z3-AA3 | AA3: 0 | AB3: 17.08.2025 | AC3: L25H009 | AD3: =-(24.5+3.2) | AE3: 18.08.2025 | AF3: L25H012 | AG3: -28 | AH3: 20.08.2025 | AI3: L25H013 | AJ3: -28 | AK3: 14.09.2025 | AL3: L25I004 | AM3: -28.1 | AN3: 17.09.2025 | AO3: L25I007 | AP3: -28.9 | AQ3: 17.09.2025 | AR3: L25I008 | AS3: -28.9 | AT3: 07.10.2025 | AU3: L25J002 | AV3: -29.1 | AY3: 0
A4: Bulk | B4: 30.10.2025 | E4: RM0041 | F4: Chlorhexidine Gluconate 20% Solution | G4: N/A (S. lot No. CHGA103525) | H4: Alam Al-Saydalah | J4: CHGA103525 | K4: 07/2024 | L4: 06/2027 | M4: NA | Q4: 220 | R4: Kg. | U4: Assay 18.83%. | V4: =Q4-S4 | W4: =Y4+AD4+AG4+AJ4+AM4+AP4+AS4+AV4+AY4+BB4+BE4+BH4+BK4 | X4: 0 | Y4: =V4-X4-Z4-AA4 | AA4: 0 | AB4: 02.11.2025 | AC4: L25K003 | AD4: -16.16 | AE4: 03.11.2025 | AF4: MR | AG4: -0.7 | AH4: 16.11.2025 | AI4: L25K006 | AJ4: -10.5 | AK4: 23.11.2025 | AL4: L25K009 | AM4: -17.5 | AN4: 28.12.2025 | AO4: L25L009 | AP4: -23.1 | AQ4: 06.01.2026 | AR4: L26A003 | AS4: -23.1 | AT4: 18.02.2026 | AU4: L26B005 | AV4: -17.5
Q5: 0 | R5: Kg. | S5: 0 | V5: =Q5-S5 | W5: =Y5+AD5+AG5+AJ5+AM5+AP5+AS5+AV5+AY5+BB5+BE5+BH5+BK5 | X5: 0 | Y5: =V5-X5-Z5-AA5 | Z5: 0 | AA5: 0 | AD5: 0 | AG5: 0 | AJ5: 0 | AM5: 0 | AP5: 0 | AS5: 0 | AV5: 0 | AY5: 0 | BB5: 0 | BE5: 0 | BH5: 0 | BK5: 0
Q6: 0 | R6: Kg. | S6: 0 | V6: =Q6-S6 | W6: =Y6+AD6+AG6+AJ6+AM6+AP6+AS6+AV6+AY6+BB6+BE6+BH6+BK6 | X6: 0 | Y6: =V6-X6-Z6-AA6 | Z6: 0 | AA6: 0 | AD6: 0 | AG6: 0 | AJ6: 0 | AM6: 0 | AP6: 0 | AS6: 0 | AV6: 0 | AY6: 0 | BB6: 0 | BE6: 0 | BH6: 0 | BK6: 0
Q7: 0 | R7: Kg. | S7: 0 | V7: =Q7-S7 | W7: =Y7+AD7+AG7+AJ7+AM7+AP7+AS7+AV7+AY7+BB7+BE7+BH7+BK7 | X7: 0 | Y7: =V7-X7-Z7-AA7 | Z7: 0 | AA7: 0 | AD7: 0 | AG7: 0 | AJ7: 0 | AM7: 0 | AP7: 0 | AS7: 0 | AV7: 0 | AY7: 0 | BB7: 0 | BE7: 0 | BH7: 0 | BK7: 0
Q8: 0 | R8: Kg. | S8: 0 | V8: =Q8-S8 | W8: =Y8+AD8+AG8+AJ8+AM8+AP8+AS8+AV8+AY8+BB8+BE8+BH8+BK8 | X8: 0 | Y8: =V8-X8-Z8-AA8 | Z8: 0 | AA8: 0 | AD8: 0 | AG8: 0 | AJ8: 0 | AM8: 0 | AP8: 0 | AS8: 0 | AV8: 0 | AY8: 0 | BB8: 0 | BE8: 0 | BH8: 0 | BK8: 0
Q9: 0 | R9: Kg. | S9: 0 | V9: =Q9-S9 | W9: =Y9+AD9+AG9+AJ9+AM9+AP9+AS9+AV9+AY9+BB9+BE9+BH9+BK9 | X9: 0 | Y9: =V9-X9-Z9-AA9 | Z9: 0 | AA9: 0 | AD9: 0 | AG9: 0 | AJ9: 0 | AM9: 0 | AP9: 0 | AS9: 0 | AV9: 0 | AY9: 0 | BB9: 0 | BE9: 0 | BH9: 0 | BK9: 0
Q10: 0 | R10: Kg. | S10: 0 | V10: =Q10-S10 | W10: =Y10+AD10+AG10+AJ10+AM10+AP10+AS10+AV10+AY10+BB10+BE10+BH10+BK10 | X10: 0 | Y10: =V10-X10-Z10-AA10 | Z10: 0 | AA10: 0 | AD10: 0 | AG10: 0 | AJ10: 0 | AM10: 0 | AP10: 0 | AS10: 0 | AV10: 0 | AY10: 0 | BB10: 0 | BE10: 0 | BH10: 0 | BK10: 0
Q11: 0 | R11: Kg. | S11: 0 | V11: =Q11-S11 | W11: =Y11+AD11+AG11+AJ11+AM11+AP11+AS11+AV11+AY11+BB11+BE11+BH11+BK11 | X11: 0 | Y11: =V11-X11-Z11-AA11 | Z11: 0 | AA11: 0 | AD11: 0 | AG11: 0 | AJ11: 0 | AM11: 0 | AP11: 0 | AS11: 0 | AV11: 0 | AY11: 0 | BB11: 0 | BE11: 0 | BH11: 0 | BK11: 0
Q12: 0 | R12: Kg. | S12: 0 | V12: =Q12-S12 | W12: =Y12+AD12+AG12+AJ12+AM12+AP12+AS12+AV12+AY12+BB12+BE12+BH12+BK12 | X12: 0 | Y12: =V12-X12-Z12-AA12 | Z12: 0 | AA12: 0 | AD12: 0 | AG12: 0 | AJ12: 0 | AM12: 0 | AP12: 0 | AS12: 0 | AV12: 0 | AY12: 0 | BB12: 0 | BE12: 0 | BH12: 0 | BK12: 0
Q13: 0 | R13: Kg. | S13: 0 | V13: =Q13-S13 | W13: =Y13+AD13+AG13+AJ13+AM13+AP13+AS13+AV13+AY13+BB13+BE13+BH13+BK13 | X13: 0 | Y13: =V13-X13-Z13-AA13 | Z13: 0 | AA13: 0 | AD13: 0 | AG13: 0 | AJ13: 0 | AM13: 0 | AP13: 0 | AS13: 0 | AV13: 0 | AY13: 0 | BB13: 0 | BE13: 0 | BH13: 0 | BK13: 0
Q14: 0 | R14: Kg. | S14: 0 | V14: =Q14-S14 | W14: =Y14+AD14+AG14+AJ14+AM14+AP14+AS14+AV14+AY14+BB14+BE14+BH14+BK14 | X14: 0 | Y14: =V14-X14-Z14-AA14 | Z14: 0 | AA14: 0 | AD14: 0 | AG14: 0 | AJ14: 0 | AM14: 0 | AP14: 0 | AS14: 0 | AV14: 0 | AY14: 0 | BB14: 0 | BE14: 0 | BH14: 0 | BK14: 0
Q15: 0 | R15: Kg. | S15: 0 | V15: =Q15-S15 | W15: =Y15+AD15+AG15+AJ15+AM15+AP15+AS15+AV15+AY15+BB15+BE15+BH15+BK15 | X15: 0 | Y15: =V15-X15-Z15-AA15 | Z15: 0 | AA15: 0 | AD15: 0 | AG15: 0 | AJ15: 0 | AM15: 0 | AP15: 0 | AS15: 0 | AV15: 0 | AY15: 0 | BB15: 0 | BE15: 0 | BH15: 0 | BK15: 0
Q16: 0 | R16: Kg. | S16: 0 | V16: =Q16-S16 | W16: =Y16+AD16+AG16+AJ16+AM16+AP16+AS16+AV16+AY16+BB16+BE16+BH16+BK16 | X16: 0 | Y16: =V16-X16-Z16-AA16 | Z16: 0 | AA16: 0 | AD16: 0 | AG16: 0 | AJ16: 0 | AM16: 0 | AP16: 0 | AS16: 0 | AV16: 0 | AY16: 0 | BB16: 0 | BE16: 0 | BH16: 0 | BK16: 0
... Q109: 0 | R109: Kg. | S109: 0 | V109: =Q109-S109 | W109: =Y109+AD109+AG109+AJ109+AM109+AP109+AS109+AV109+AY109+BB109+BE109+BH109+BK109 | X109: 0 | Y109: =V109-X109-Z109-AA109 | Z109: 0 | AA109: 0 | AD109: 0 | AG109: 0 | AJ109: 0 | AM109: 0 | AP109: 0 | AS109: 0 | AV109: 0 | AY109: 0 | BB109: 0 | BE109: 0 | BH109: 0 | BK109: 0

Sheet Inner & Assembled
A1: Item Category | B1: Rec. Date | C1: Doc. No. | D1: Item Code | E1: Batch No. | F1: Item Name | G1: MFG. D. | H1: Exp. D. | I1: Remark | J1: Received QTY | K1: Sampled Qty | L1: Bigening Qty | M1: Unit | N1: Total stock Qty | O1: Current Released | P1: Quarantine | Q1: Released | R1: Restricted | S1: Reject | T1: Date (1) | U1: Doc No. (1) | V1: Qty (1) | W1: Date (2) | X1: Doc No. (2) | Y1: Qty (2) | Z1: Date (3) | AA1: Doc No. (3) | AB1: Qty (3) | AC1: Date (4) | AD1: Doc No. (4) | AE1: Qty (4) | AF1: Date (5) | AG1: Doc No. (5) | AH1: Qty (5) | AI1: Date (6) | AJ1: Doc No. (6) | AK1: Qty (6) | AL1: Date (7) | AM1: Doc No. (7) | AN1: Qty (7) | AO1: Date (8) | AP1: Doc No. (8) | AQ1: Qty (8) | AR1: Date (9) | AS1: Doc No. (9) | AT1: Qty (9) | AU1: Date (10) | AV1: Doc No. (10) | AW1: Qty (10) | AX1: Date (11) | AY1: Doc No. (11) | AZ1: Qty (11) | BA1: Date (12) | BB1: Doc No. (12) | BC1: Qty (12)
A2: Inner | D2: BP0014 | E2: 25IBP009 | F2: Inner filled tube 100*18mm FAS Chlorex 2% | G2: 45748 | H2: 46844 | J2: 96 | L2: =J2-K2 | M2: No. | N2: =P2+Q2+R2+S2 | O2: =Q2+V2+Y2+AB2+AE2+AH2+AK2+AN2+AQ2+AT2+AW2+AZ2+BC2 | Q2: =L2-S2-R2-P2 | T2: 11.11.2025 | U2: 19 | V2: -10 | W2: 11.11.2025 | X2: 20 | Y2: -10
A3: Inner | D3: BP0014 | E3: 25IBP013 | F3: Inner filled tube 100*18mm FAS Chlorex 2% | G3: 45778 | H3: 46874 | J3: 55100 | L3: =J3-K3 | M3: No. | N3: =P3+Q3+R3+S3 | O3: =Q3+V3+Y3+AB3+AE3+AH3+AK3+AN3+AQ3+AT3+AW3+AZ3+BC3 | Q3: =L3-S3-R3-P3 | T3: 29.06.2025 | U3: L25F007 | V3: -55100 | W3: 14.07.2025 | X3: R-L25F007 | Y3: 137
A4: Inner | D4: BP0016 | E4: 24IBP019 | F4: Inner filled tube-FAS Chlorex 2% Sterile Solution-118X23mm | G4: 45474 | H4: 46569 | J4: 12345 | L4: =J4-K4 | M4: No. | N4: =P4+Q4+R4+S4 | O4: =Q4+V4+Y4+AB4+AE4+AH4+AK4+AN4+AQ4+AT4+AW4+AZ4+BC4 | Q4: =L4-S4-R4-P4 | T4: 20.07.2025 | U4: L25G007 | V4: -12345 | W4: 23.07.2025 | X4: R-L25G007 | Y4: 93 | Z4: 11.11.2025 | AA4: 27 | AB4: -10 | AC4: 11.11.2025 | AD4: 26 | AE4: -10
A5: Inner | B5: 03.08.2025 | C5: 944 | D5: BP0016 | E5: 25IBP024 | F5: Inner filled tube-FAS Chlorex 2% Sterile Solution-118X23mm | G5: 45839 | H5: 46935 | J5: 22850 | L5: 22850 | M5: No. | N5: 22850 | O5: =Q5+V5+Y5+AB5+AE5+AH5+AK5+AN5+AQ5+AT5+AW5+AZ5+BC5 | Q5: 22850 | T5: 03.08.2025 | U5: L25G012 | V5: -22850 | W5: 17.08.2025 | X5: R-L25G012 | Y5: 21
A6: Inner | D6: BP0017 | E6: 25IBP011 | F6: Inner filled tube 81*15mm FAS Chlorex 2% | G6: 45748 | H6: 46844 | J6: 29440 | L6: =J6-K6 | M6: No. | N6: =P6+Q6+R6+S6 | O6: =Q6+V6+Y6+AB6+AE6+AH6+AK6+AN6+AQ6+AT6+AW6+AZ6+BC6 | Q6: =L6-S6-R6-P6 | T6: 19.06.2025 | U6: L25F003 | V6: -6000 | W6: 22.06.2025 | X6: L25F003 | Y6: 151 | Z6: 22.07.2025 | AA6: L25G0008 | AB6: -10500 | AC6: 24.07.2025 | AD6: L25G010 | AE6: -6000 | AF6: 29.07.2025 | AG6: R-L25G010 | AH6: 20 | AI6: 28.07.2025 | AJ6: L25G013 | AK6: -7091 | AL6: 11.11.2025 | AM6: 13 | AN6: -10
A7: Inner | D7: BP0017 | E7: 25IBP006 | F7: Inner filled tube 81*15mm FAS Chlorex 2% | G7: 45689 | H7: 46784 | J7: 33500 | L7: =J7-K7 | M7: No. | N7: =P7+Q7+R7+S7 | O7: =Q7+V7+Y7+AB7+AE7+AH7+AK7+AN7+AQ7+AT7+AW7+AZ7+BC7 | Q7: =L7-S7-R7-P7 | T7: 26-05-2025 | U7: L25006 | V7: -33500 | W7: 04.06.2025 | X7: R-L25006 | Y7: 233
A8: Inner | B8: 09.07.2025 | C8: 890 | D8: BP0039 | E8: 25IBP022 | F8: FAS CHLOREX 1% INNER FILLED TUBE 77*11MM 3ML Tecnomaco | G8: 45839 | H8: 46935 | J8: 26550 | L8: 26550 | M8: No. | N8: 26550 | O8: =Q8+V8+Y8+AB8+AE8+AH8+AK8+AN8+AQ8+AT8+AW8+AZ8+BC8 | Q8: 26550 | T8: 15.07.2025 | U8: L25G005 | V8: -26550 | W8: 18.08.2025 | X8: R-L25G005 | Y8: 164
A9: Inner | D9: BP0039 | E9: 25IBP012 | F9: FAS CHLOREX 1% INNER FILLED TUBE 77*81MM 3ML Tecnomaco | G9: 45748 | H9: 46844 | J9: 825 | L9: =J9-K9 | M9: No. | N9: =P9+Q9+R9+S9 | O9: =Q9+V9+Y9+AB9+AE9+AH9+AK9+AN9+AQ9+AT9+AW9+AZ9+BC9 | Q9: =L9-S9-R9-P9 | V9: 0 | Y9: 0
A10: Inner | B10: 06.07.2025 | C10: 882 | D10: BP0049 | E10: 25IBP021 | F10: FAS CHLOREX 1% INNER FILLED TUBE 81*15MM 6ML OMAS | G10: 45839 | H10: 46935 | J10: 6550 | L10: 6550 | M10: No. | N10: 6550 | O10: =Q10+V10+Y10+AB10+AE10+AH10+AK10+AN10+AQ10+AT10+AW10+AZ10+BC10 | Q10: 6550 | T10: 10.07.2025 | U10: L25G004 | V10: -6550 | W10: 10.08.2025 | X10: R-L25G004 | Y10: 74
A11: Assambled | B11: 10.09.2025 | C11: 1034 | D11: PP0039 | E11: 25IPP021 | F11: Assembled Outer Tube (155*23mm) for OMAS applicator clear | G11: 45901 | H11: 45992 | J11: 15004 | L11: =J11-K11 | M11: No. | N11: =P11+Q11+R11+S11 | O11: =Q11+V11+Y11+AB11+AE11+AH11+AK11+AN11+AQ11+AT11+AW11+AZ11+BC11 | Q11: =L11-S11-R11-P11 | S11: 59 | T11: 11.09.2025 | U11: L25I003 | V11: -11754 | W11: 14.09.2025 | X11: MR250168 | Y11: -260 | Z11: 22.09.2025 | AA11: L25I010 | AB11: -2990 | AC11: 22.09.2025 | AD11: R-L25I003 | AE11: 79 | AF11: 11.11.2025 | AG11: 26 | AH11: -10 | AI11: 11.11.2025 | AJ11: 16 | AK11: -10
A12: Assambled | B12: 24.09.2025 | C12: 1059 | D12: PP0039 | E12: 25IPP023 | F12: Assembled Outer Tube (155*23mm) for OMAS applicator clear | G12: 45925 | H12: 46016 | J12: 15116 | L12: =J12-K12 | M12: No. | N12: =P12+Q12+R12+S12 | O12: =Q12+V12+Y12+AB12+AE12+AH12+AK12+AN12+AQ12+AT12+AW12+AZ12+BC12 | Q12: =L12-S12-R12-P12 | S12: 2674 | T12: 24.09.2025 | U12: L25I010 | V12: -11996 | W12: 28.09.2025 | X12: MR250184 | Y12: -520 | Z12: 29.09.2025 | AA12: L25I010 | AB12: 74
A13: Inner | B13: 19.10.2025 | C13: 1112 | D13: BP0047 | E13: 25IBP032 | F13: FAS CHLOREX 2% Inner filled tube 1ml technomaco | G13: 45931 | H13: 47027 | J13: 29750 | L13: =J13-K13 | M13: No. | N13: =P13+Q13+R13+S13 | O13: =Q13+V13+Y13+AB13+AE13+AH13+AK13+AN13+AQ13+AT13+AW13+AZ13+BC13 | Q13: =L13-S13-R13-P13 | T13: 27.10.2025 | U13: L25J013 | V13: -20000 | W13: 11.11.2025 | X13: 39 | Y13: -20 | Z13: 23.02.2026 | AA13: L26B010 | AB13: -3730 | AE13: 0 | AH13: 0
A14: Assambled | B14: 23.10.2025 | C14: 1127 | D14: PP0038 | E14: 25IPP029 | F14: Assembled Outer Tube 128*18mm clear | G14: 45931 | H14: 46388 | J14: 13981 | L14: =J14-K14 | M14: No. | N14: =P14+Q14+R14+S14 | O14: =Q14+V14+Y14+AB14+AE14+AH14+AK14+AN14+AQ14+AT14+AW14+AZ14+BC14 | Q14: =L14-S14-R14-P14 | T14: 11.11.2025 | U14: 16 | V14: -10 | W14: 24.12.2025 | X14: 67 | Y14: -641 | Z14: 29.12.2025 | AA14: R-0067 | AB14: 418 | AC14: 07.01.2026 | AD14: L26A005 | AE14: -3670 | AF14: 07.01.2026 | AG14: L25A004 | AH14: -3638 | AI14: 12.01.2026 | AJ14: MR26007/8 | AK14: =-(230+230) | AL14: 15.01.2026 | AM14: R-L26A004 | AN14: 116
A15: Assambled | B15: 30.10.2025 | C15: 1145 | D15: PP0054 | E15: 25IPP030 | F15: Assembled Outer Tube 128*18mm Tinted | G15: 45931 | H15: 46419 | J15: 25693 | L15: =J15-K15 | M15: No. | N15: =P15+Q15+R15+S15 | O15: =Q15+V15+Y15+AB15+AE15+AH15+AK15+AN15+AQ15+AT15+AW15+AZ15+BC15 | Q15: =L15-S15-R15-P15 | T15: 11.11.2025 | U15: 19 | V15: -10 | W15: 11.11.2025 | X15: 20 | Y15: -10 | Z15: 10.02.2026 | AA15: L26B003 | AB15: -15333 | AC15: 16.02.2026 | AD15: R-L26B003 | AE15: 187
A16: Assambled | B16: 04.11.2025 | C16: 1153 | D16: PP0038 | E16: 25IPP031 | F16: Assembled Outer Tube 128*18mm clear | G16: 45931 | H16: 46419 | J16: 19995 | L16: =J16-K16 | M16: No. | N16: =P16+Q16+R16+S16 | O16: =Q16+V16+Y16+AB16+AE16+AH16+AK16+AN16+AQ16+AT16+AW16+AZ16+BC16 | Q16: =L16-S16-R16-P16 | T16: 03.12.2025 | U16: MR250249 | V16: -20
A17: Soln | B17: 24.12.2025 | C17: 1348 | D17: BP0067 | E17: 25IBP047 | F17: FAS IODO Soln. 1% | G17: 24.12.2025 | H17: 27.12.2025 | J17: 4.1 | L17: =J17-K17 | M17: kg | N17: =P17+Q17+R17+S17 | O17: =Q17+V17+Y17+AB17+AE17+AH17+AK17+AN17+AQ17+AT17+AW17+AZ17+BC17 | Q17: =L17-S17-R17-P17 | S17: 1.49 | T17: 25.12.2025 | U17: L25L004 | V17: -4.1 | W17: 28.12.2025 | X17: 67 | Y17: 1.55 | Z17: 25.01.2026 | AA17: MR260015 | AB17: -0.06 | AC17: 24.02.2026 | AD17: MR260039 | AE17: -0.06
A18: Inner | B18: 30.12.2025 | C18: 1358 | D18: BP0047 | E18: 25IBP045 | F18: FAS CHLOREX 2% Inner filled tube 1ml technomaco | G18: 45992 | H18: 47088 | J18: 31150 | L18: =J18-K18 | M18: No. | N18: =P18+Q18+R18+S18 | O18: =Q18+V18+Y18+AB18+AE18+AH18+AK18+AN18+AQ18+AT18+AW18+AZ18+BC18 | Q18: =L18-S18-R18-P18 | T18: 31.12.2025 | U18: L25L006 | V18: -25150
A19: Inner | B19: 05.01.2026 | C19: 1370 | D19: BP0048 | E19: 25IBP050 | F19: FAS CHLOREX 2% Inner filled tube 81*15MM 6ML | G19: 45992 | H19: 47088 | J19: 3665 | L19: =J19-K19 | M19: No. | N19: =P19+Q19+R19+S19 | O19: =Q19+V19+Y19+AB19+AE19+AH19+AK19+AN19+AQ19+AT19+AW19+AZ19+BC19 | Q19: =L19-S19-R19-P19
A20: Assambled | B20: 01.01.2026 | C20: 1365 | D20: PP0050 | E20: 25IPP036 | F20: Assembled outer tube (155*23mm) tinted | G20: 45992 | H20: 46204 | J20: 12480 | L20: =J20-K20 | M20: No. | N20: =P20+Q20+R20+S20 | O20: =Q20+V20+Y20+AB20+AE20+AH20+AK20+AN20+AQ20+AT20+AW20+AZ20+BC20 | Q20: =L20-S20-R20-P20 | T20: 01.01.2026 | U20: L26A001 | V20: -2990 | W20: 15.01.2026 | X20: L26A010 | Y20: -3770 | Z20: 01.02.2026 | AA20: L26A015 | AB20: -2210 | AC20: 18.01.2026 | AD20: 1386 | AE20: 16759 | AF20: 23.02.2026 | AG20: L26B008 | AH20: -8580
A21: Assambled | B21: 21.12.2025 | C21: 1343 | D21: PP0053 | E21: 25IPP034 | F21: Assembled outer tube 105*15mm for OMAS - Tinted | G21: 45992 | H21: 46478 | J21: 28085 | L21: 28085 | M21: No. | N21: 28085 | O21: =Q21+V21+Y21+AB21+AE21+AH21+AK21+AN21+AQ21+AT21+AW21+AZ21+BC21 | Q21: 28085 | T21: 21.12.2025 | U21: L25L003 | V21: -21808 | W21: 25.12.2025 | X21: R-L25L003 | Y21: 1059 | Z21: 07.01.2026 | AA21: L26A006 | AB21: -3477 | AC21: 11.01.2026 | AD21: R-L26A006 | AE21: 172 | AF21: 15.01.2026 | AG21: L26A009 | AH21: -4031 | AI21: 21.01.2026 | AJ21: R-L26A009 | AK21: 111
A22: Assambled | B22: 29.01.2026 | C22: 1489 | D22: PP0039 | E22: 26IPP003 | F22: Assembled outer tube (155*23mm) Clear | G22: 46023 | H22: 46266 | J22: 4266 | L22: =J22-K22 | M22: No. | N22: =P22+Q22+R22+S22 | O22: =Q22+V22+Y22+AB22+AE22+AH22+AK22+AN22+AQ22+AT22+AW22+AZ22+BC22 | Q22: =L22-S22-R22-P22
A23: Assambled | B23: 29.01.2026 | C23: 1488 | D23: PP0039 | E23: 26IPP003 | F23: Assembled outer tube (155*23mm) Clear | G23: 46023 | H23: 46266 | J23: 20800 | L23: =J23-K23 | M23: No. | N23: =P23+Q23+R23+S23 | O23: =Q23+V23+Y23+AB23+AE23+AH23+AK23+AN23+AQ23+AT23+AW23+AZ23+BC23 | Q23: =L23-S23-R23-P23
A24: Assambled | B24: 03.02.2026 | C24: 1508 | D24: PP0037 | E24: 26IPP005 | F24: Assembled outer tube (105*15mm) Clear | G24: 46054 | H24: 46508 | J24: 13600 | L24: 13600 | M24: No. | N24: 13600 | O24: =Q24+V24+Y24+AB24+AE24+AH24+AK24+AN24+AQ24+AT24+AW24+AZ24+BC24 | Q24: 13600 | T24: 03.02.2026 | U24: L26B002 | V24: -13600 | W24: 04.02.2026 | X24: R-L26B001 | Y24: 147 | Z24: 16.02.2026 | AA24: L26B004 | AB24: -147
A25: Inner | B25: 05.02.2026 | C25: 1520 | D25: BP0016 | E25: 26IBP007 | F25: FAS Chlorex 2% Inner Filled 118*23mm OMAS Sub-Batch 2 | G25: 46054 | H25: 47150 | J25: 9000 | L25: =J25-K25 | M25: No. | N25: =P25+Q25+R25+S25 | O25: =Q25+V25+Y25+AB25+AE25+AH25+AK25+AN25+AQ25+AT25+AW25+AZ25+BC25 | Q25: =L25-S25-R25-P25 | T25: 05.02.2026 | U25: L26A016 | V25: -9000
A26: Assambled | B26: 05.02.2026 | C26: 1519 | D26: PP0037 | E26: 26IPP005 | F26: Assembled outer tube (105*15mm) Clear | G26: 46054 | H26: 46508 | J26: 13431 | L26: =J26-K26 | M26: No. | N26: =P26+Q26+R26+S26 | O26: =Q26+V26+Y26+AB26+AE26+AH26+AK26+AN26+AQ26+AT26+AW26+AZ26+BC26 | Q26: =L26-S26-R26-P26 | T26: 05.02.2026 | U26: R-L26B002 | V26: 365 | W26: 16.02.2026 | X26: L26B004 | Y26: -13796
A27: Inner | B27: 08.02.2026 | C27: 1521 | D27: BP0016 | E27: 26IBP007 | F27: FAS Chlorex 2% Inner Filled 118*23mm OMAS Sub-Batch 2 | G27: 46054 | H27: 47150 | J27: 5000 | L27: =J27-K27 | M27: No. | N27: =P27+Q27+R27+S27 | O27: =Q27+V27+Y27+AB27+AE27+AH27+AK27+AN27+AQ27+AT27+AW27+AZ27+BC27 | Q27: =L27-S27-R27-P27 | T27: 08.02.2026 | U27: L26A016 | V27: -5000
A28: Inner | B28: 09.02.2026 | C28: 1523 | D28: BP0016 | E28: 26IBP007 | F28: FAS Chlorex 2% Inner Filled 118*23mm OMAS Sub-Batch 2 | G28: 46054 | H28: 47150 | J28: 7000 | L28: =J28-K28 | M28: No. | N28: =P28+Q28+R28+S28 | O28: =Q28+V28+Y28+AB28+AE28+AH28+AK28+AN28+AQ28+AT28+AW28+AZ28+BC28 | Q28: =L28-S28-R28-P28 | T28: 09.02.2026 | U28: L26A015 | V28: -7000
A29: Inner | B29: 10.02.2026 | C29: 1525 | D29: BP0016 | E29: 26IBP007 | F29: FAS Chlorex 2% Inner Filled 118*23mm OMAS Sub-Batch 2 | G29: 46054 | H29: 47150 | J29: 7500 | L29: =J29-K29 | M29: No. | N29: =P29+Q29+R29+S29 | O29: =Q29+V29+Y29+AB29+AE29+AH29+AK29+AN29+AQ29+AT29+AW29+AZ29+BC29 | Q29: =L29-S29-R29-P29 | T29: 10.02.2026 | U29: L26A015 | V29: -7500
A30: Assambled | B30: 10.02.2026 | C30: 1528 | D30: PP0050 | E30: 26IPP004 | F30: Assembled outer tube (155*23mm) tinted | G30: 46054 | H30: 46357 | J30: 20800 | L30: =J30-K30 | M30: No. | N30: =P30+Q30+R30+S30 | O30: =Q30+V30+Y30+AB30+AE30+AH30+AK30+AN30+AQ30+AT30+AW30+AZ30+BC30 | Q30: =L30-S30-R30-P30 | T30: 10.02.2026 | U30: 1529 | V30: 4608
A31: Inner | B31: 11.02.2026 | C31: 1532 | D31: BP0016 | E31: 26IBP007 | F31: FAS Chlorex 2% Inner Filled 118*23mm OMAS Sub-Batch 2 | G31: 46054 | H31: 47150 | J31: 8400 | L31: =J31-K31 | M31: No. | N31: =P31+Q31+R31+S31 | O31: =Q31+V31+Y31+AB31+AE31+AH31+AK31+AN31+AQ31+AT31+AW31+AZ31+BC31 | Q31: =L31-S31-R31-P31 | T31: 11.02.2026 | U31: L26A015 | V31: -8400
A32: Inner | B32: 11.02.2026 | C32: 1534 | D32: BP0014 | E32: 26IBP009 | F32: FAS Chlorex 2% Inner Filled 100*18mm OMAS | G32: 46054 | H32: 47150 | J32: 5320 | L32: =J32-K32 | M32: No. | N32: =P32+Q32+R32+S32 | O32: =Q32+V32+Y32+AB32+AE32+AH32+AK32+AN32+AQ32+AT32+AW32+AZ32+BC32 | Q32: =L32-S32-R32-P32 | T32: 11.02.2026 | U32: L26B003 | V32: -5320
A33: Inner | B33: 12.02.2026 | C33: 1536 | D33: BP0014 | E33: 26IBP010 | F33: FAS Chlorex 2% Inner Filled 100*18mm OMAS | G33: 46054 | H33: 47150 | J33: 4000 | L33: =J33-K33 | M33: No. | N33: =P33+Q33+R33+S33 | O33: =Q33+V33+Y33+AB33+AE33+AH33+AK33+AN33+AQ33+AT33+AW33+AZ33+BC33 | Q33: =L33-S33-R33-P33 | T33: 12.02.2026 | U33: L26B003 | V33: -4000
A34: Inner | B34: 12.02.2026 | C34: 1536 | D34: BP0014 | E34: 26IBP010 | F34: FAS Chlorex 2% Inner Filled 100*18mm OMAS | G34: 46054 | H34: 47150 | J34: 3000 | L34: =J34-K34 | M34: No. | N34: =P34+Q34+R34+S34 | O34: =Q34+V34+Y34+AB34+AE34+AH34+AK34+AN34+AQ34+AT34+AW34+AZ34+BC34 | Q34: =L34-S34-R34-P34 | T34: 12.02.2026 | U34: L26B003 | V34: -3000
A35: Inner | B35: 15.02.2026 | C35: 1540 | D35: BP0014 | E35: 26IBP010 | F35: FAS Chlorex 2% Inner Filled 100*18mm OMAS | G35: 46054 | H35: 47150 | J35: 2780 | L35: =J35-K35 | M35: No. | N35: =P35+Q35+R35+S35 | O35: =Q35+V35+Y35+AB35+AE35+AH35+AK35+AN35+AQ35+AT35+AW35+AZ35+BC35 | Q35: =L35-S35-R35-P35 | T35: 15.02.2026 | U35: L26B003 | V35: -2780
A36: Assambled | B36: 17.02.2026 | C36: 1545 | D36: PP0037 | E36: 26IPP006 | F36: Assembled outer tube (105*15mm) Clear | G36: 46054 | H36: 46508 | J36: 29585 | L36: =J36-K36 | M36: No. | N36: =P36+Q36+R36+S36 | O36: =Q36+V36+Y36+AB36+AE36+AH36+AK36+AN36+AQ36+AT36+AW36+AZ36+BC36 | Q36: =L36-S36-R36-P36
A37: Inner | B37: 17.02.2026 | C37: 1544 | D37: BP0017 | E37: 26IBP011 | F37: Inner filled tube 81*15mm FAS Chlorex 2% | G37: 46054 | H37: 47150 | J37: 6000 | L37: =J37-K37 | M37: No. | N37: =P37+Q37+R37+S37 | O37: =Q37+V37+Y37+AB37+AE37+AH37+AK37+AN37+AQ37+AT37+AW37+AZ37+BC37 | Q37: =L37-S37-R37-P37 | T37: 17.02.2026 | U37: L26B004 | V37: -6000 | W37: 19.02.2026 | X37: 1558 | Y37: 27000 | Z37: 19.02.2026 | AA37: L26B004 | AB37: -27000
A38: Inner | B38: 23.02.2026 | C38: 1559 | D38: BP0017 | E38: 26IBP011 | F38: Inner filled tube 81*15mm FAS Chlorex 2% | G38: 46054 | H38: 47150 | J38: 3210 | L38: =J38-K38 | M38: No. | N38: =P38+Q38+R38+S38 | O38: =Q38+V38+Y38+AB38+AE38+AH38+AK38+AN38+AQ38+AT38+AW38+AZ38+BC38 | Q38: =L38-S38-R38-P38 | T38: 23.02.2026 | U38: L26B004 | V38: -3210
A39: Assambled | B39: 30.10.2025 | C39: 1145 | D39: PP0054 | E39: 26IPP007 | F39: Assembled Outer Tube 128*18mm Tinted | G39: 46054 | H39: 46478 | J39: 14834 | L39: =J39-K39 | M39: No. | N39: =P39+Q39+R39+S39 | O39: =Q39+V39+Y39+AB39+AE39+AH39+AK39+AN39+AQ39+AT39+AW39+AZ39+BC39 | Q39: =L39-S39-R39-P39
L40: =J40-K40 | N40: =P40+Q40+R40+S40 | O40: =Q40+V40+Y40+AB40+AE40+AH40+AK40+AN40+AQ40+AT40+AW40+AZ40+BC40 | Q40: =L40-S40-R40-P40
...

Sheet Stagnant I & A
A1: Item Category | B1: Rec. Date | C1: Doc. No. | D1: Item Code | E1: Batch No. | F1: Item Name | G1: Manf. Date | H1: Exp. Date | I1: Remarks | J1: Received QTY | K1: Sampled Qty | L1: Bigening Qty | M1: Unit | N1: Total stock Qty | O1: Current Released | P1: Quarantine | Q1: Released | R1: Restricted | S1: Reject | T1: Date (1) | U1: Doc No. (1) | V1: Qty (1) | W1: Date (2) | X1: Doc No. (2) | Y1: Qty (2) | Z1: Date (3) | AA1: Doc No. (3) | AB1: Qty (3) | AC1: Date (4) | AD1: Doc No. (4) | AE1: Qty (4) | AF1: Date (5) | AG1: Doc No. (5) | AH1: Qty (5) | AI1: Date (6) | AJ1: Doc No. (6) | AK1: Qty (6) | AL1: Date (7) | AM1: Doc No. (7) | AN1: Qty (7) | AO1: Date (8) | AP1: Doc No. (8) | AQ1: Qty (8) | AR1: Date (9) | AS1: Doc No. (9) | AT1: Qty (9) | AU1: Date (10) | AV1: Doc No. (10) | AW1: Qty (10) | AX1: Date (11) | AY1: Doc No. (11) | AZ1: Qty (11) | BA1: Date (12) | BB1: Doc No. (12) | BC1: Qty (12)
A2: Inner | D2: BP0028 | E2: 24IBP006 | F2: Inner filled tube-chlorhexidine 2% solution 118*23 mm | G2: september.-2024 | H2: september.-2027 | I2: Trials | J2: 420 | L2: =J2-K2 | M2: No. | N2: =P2+Q2+R2+S2 | O2: =Q2+V2+Y2+AB2+AE2+AH2+AK2+AN2+AQ2+AT2+AW2+AZ2-BC2 | Q2: =L2-S2-R2-P2
A3: Inner | D3: BP0026 | E3: 24IBP007 | F3: Inner filled tube-chlorhexidine 2% solution 81*15 mm | G3: september.-2024 | H3: september.-2027 | I3: Trials | J3: 7850 | L3: =J3-K3 | M3: No. | N3: =P3+Q3+R3+S3 | O3: =Q3+V3+Y3+AB3+AE3+AH3+AK3+AN3+AQ3+AT3+AW3+AZ3-BC3 | Q3: =L3-S3-R3-P3
A4: Inner | D4: BP0029 | E4: 24IBP009 | F4: Inner filled tube-chlorhexidine 2% solution 81*15 mm | G4: september.-2024 | H4: september.-2027 | I4: Trials | J4: 2850 | L4: =J4-K4 | M4: No. | N4: =P4+Q4+R4+S4 | O4: =Q4+V4+Y4+AB4+AE4+AH4+AK4+AN4+AQ4+AT4+AW4+AZ4-BC4 | Q4: =L4-S4-R4-P4
A5: Inner | D5: BP0030 | E5: 24IBP010 | F5: Inner filled tube-chlorhexidine 2% solution 118*23 mm | G5: september.-2024 | H5: september.-2027 | I5: Trials | J5: 685 | L5: =J5-K5 | M5: No. | N5: =P5+Q5+R5+S5 | O5: =Q5+V5+Y5+AB5+AE5+AH5+AK5+AN5+AQ5+AT5+AW5+AZ5-BC5 | Q5: =L5-S5-R5-P5
L6: =J6-K6 | N6: =P6+Q6+R6+S6 | O6: =Q6+V6+Y6+AB6+AE6+AH6+AK6+AN6+AQ6+AT6+AW6+AZ6+BC6 | Q6: =L6-S6-R6-P6
L7: =J7-K7 | N7: =P7+Q7+R7+S7 | O7: =Q7+V7+Y7+AB7+AE7+AH7+AK7+AN7+AQ7+AT7+AW7+AZ7+BC7 | Q7: =L7-S7-R7-P7
L8: =J8-K8 | N8: =P8+Q8+R8+S8 | O8: =Q8+V8+Y8+AB8+AE8+AH8+AK8+AN8+AQ8+AT8+AW8+AZ8+BC8 | Q8: =L8-S8-R8-P8
L9: =J9-K9 | N9: =P9+Q9+R9+S9 | O9: =Q9+V9+Y9+AB9+AE9+AH9+AK9+AN9+AQ9+AT9+AW9+AZ9+BC9 | Q9: =L9-S9-R9-P9
L10: =J10-K10 | N10: =P10+Q10+R10+S10 | O10: =Q10+V10+Y10+AB10+AE10+AH10+AK10+AN10+AQ10+AT10+AW10+AZ10+BC10 | Q10: =L10-S10-R10-P10
L11: =J11-K11 | N11: =P11+Q11+R11+S11 | O11: =Q11+V11+Y11+AB11+AE11+AH11+AK11+AN11+AQ11+AT11+AW11+AZ11+BC11 | Q11: =L11-S11-R11-P11
L12: =J12-K12 | N12: =P12+Q12+R12+S12 | O12: =Q12+V12+Y12+AB12+AE12+AH12+AK12+AN12+AQ12+AT12+AW12+AZ12+BC12 | Q12: =L12-S12-R12-P12
L13: =J13-K13 | N13: =P13+Q13+R13+S13 | O13: =Q13+V13+Y13+AB13+AE13+AH13+AK13+AN13+AQ13+AT13+AW13+AZ13+BC13 | Q13: =L13-S13-R13-P13
L14: =J14-K14 | N14: =P14+Q14+R14+S14 | O14: =Q14+V14+Y14+AB14+AE14+AH14+AK14+AN14+AQ14+AT14+AW14+AZ14+BC14 | Q14: =L14-S14-R14-P14
L15: =J15-K15 | N15: =P15+Q15+R15+S15 | O15: =Q15+V15+Y15+AB15+AE15+AH15+AK15+AN15+AQ15+AT15+AW15+AZ15+BC15 | Q15: =L15-S15-R15-P15
L16: =J16-K16 | N16: =P16+Q16+R16+S16 | O16: =Q16+V16+Y16+AB16+AE16+AH16+AK16+AN16+AQ16+AT16+AW16+AZ16+BC16 | Q16: =L16-S16-R16-P16
L17: =J17-K17 | N17: =P17+Q17+R17+S17 | O17: =Q17+V17+Y17+AB17+AE17+AH17+AK17+AN17+AQ17+AT17+AW17+AZ17+BC17 | Q17: =L17-S17-R17-P17
... L856: =J856-K856 | N856: =P856+Q856+R856+S856 | O856: =Q856+V856+Y856+AB856+AE856+AH856+AK856+AN856+AQ856+AT856+AW856+AZ856+BC856 | Q856: =L856-S856-R856-P856

Sheet Historical R&PM
A1: Item Category | B1: Rece. Date | C1: PO No. | D1: Doc. No. | E1: Item Code | F1: Item Name | G1: Control No. | H1: Manufacturer Name | I1: Supplier | J1: Supp. Lot No | K1: Mfg. Date | M1: Exp. Date | O1: Retest Date | R1: No. of packs | S1: Qty per packs | T1: Loose Pack | U1: Received Qty | V1: Unit | W1: Sample Qty | X1: Date | Y1: Remarks | Z1: Beg. Balance | AA1: Current released | AB1: Quarantine | AC1: Unrestricted | AD1: Restricted | AE1: Rejected | AF1: Date (1) | AG1: Doc No. (1) | AH1: Qty (1) | AI1: Date (2) | AJ1: Doc No. (2) | AK1: Qty (2) | AL1: Date (3) | AM1: Doc No. (3) | AN1: Qty (3) | AO1: Date (4) | AP1: Doc No. (4) | AQ1: Qty (4) | AR1: Date (5) | AS1: Doc No. (5) | AT1: Qty (5) | AU1: Date (6) | AV1: Doc No. (6) | AW1: Qty (6) | AX1: Date (7) | AY1: Doc No. (7) | AZ1: Qty (7) | BA1: Date (8) | BB1: Doc No. (8) | BC1: Qty (8) | BD1: Date (9) | BE1: Doc No. (9) | BF1: Qty (9) | BG1: Date (10) | BH1: Doc No. (10) | BI1: Qty (10) | BJ1: Date (11) | BK1: Doc No. (11) | BL1: Qty (11) | BM1: Date (12) | BN1: Doc No. (12) | BO1: Qty (12)
A2: PP | B2: 15/2/2023 | C2: NA | D2: 2300035 | E2: SP0026 | F2: Label for Laparoscopic Trocar Disposable [5mm obturator*1+75mm sleeve*1] -Model No.:FAS05075N | G2: SP2300035 | H2: NA | J2: NA | K2: February.-2023 | M2: February.-2026 | O2: NA | U2: 0 | V2: No. | Y2: Dispatched | Z2: =U2-W2 | AA2: =AC2+AH2+AK2+AN2+AQ2+AT2+AW2+AZ2+BC2+BF2+BI2+BL2+BO2 | AB2: 0 | AC2: =Z2-AD2-AE2-AB2 | AE2: 0 | AH2: 0
A3: SPM | B3: 15/2/2023 | C3: NA | D3: 2300036 | E3: SP0028 | F3: Label for Laparoscopic Trocar Disposable [5mm obturator*1+75mm sleeve*1] Model No.:FAS05075P | G3: SP2300036 | H3: NA | J3: NA | K3: February.-2023 | M3: February.-2026 | O3: NA | U3: 0 | V3: No. | Y3: Dispatched | Z3: =U3-W3 | AA3: =AC3+AH3+AK3+AN3+AQ3+AT3+AW3+AZ3+BC3+BF3+BI3+BL3+BO3 | AB3: 0 | AC3: =Z3-AD3-AE3-AB3 | AE3: 0
A4: SPM | B4: 15/2/2023 | C4: NA | D4: 2300037 | E4: SP0029 | F4: Label for Laparoscopic Trocar Disposable [5mm obturator*1+75mm sleeve*1] Model No.:FAS05075V | G4: SP2300037 | H4: NA | J4: NA | K4: February.-2023 | M4: February.-2026 | O4: NA | U4: 0 | V4: No. | Y4: Dispatched | Z4: =U4-W4 | AA4: =AC4+AH4+AK4+AN4+AQ4+AT4+AW4+AZ4+BC4+BF4+BI4+BL4+BO4 | AB4: 0 | AC4: =Z4-AD4-AE4-AB4 | AE4: 0
A5: SPM | B5: 15/2/2023 | C5: NA | D5: 2300038 | E5: SP0020 | F5: Label for Laparoscopic Trocar Disposable [5mm obturator*1+100mm sleeve*1] Model No.:FAS05100N | G5: SP2300038 | H5: NA | J5: NA | K5: February.-2023 | M5: February.-2026 | O5: NA | U5: 0 | V5: No. | Y5: Dispatched | Z5: =U5-W5 | AA5: =AC5+AH5+AK5+AN5+AQ5+AT5+AW5+AZ5+BC5+BF5+BI5+BL5+BO5 | AB5: 0 | AC5: =Z5-AD5-AE5-AB5 | AE5: 0
A6: SPM | B6: 15/2/2023 | C6: NA | D6: 2300039 | E6: SP0024 | F6: Label for Laparoscopic Trocar Disposable [5mm obturator*1+100mm sleeve*1] Model No.:FAS05100P | G6: SP2300039 | H6: NA | J6: NA | K6: February.-2023 | M6: February.-2026 | O6: NA | U6: 0 | V6: No. | Y6: Dispatched | Z6: =U6-W6 | AA6: =AC6+AH6+AK6+AN6+AQ6+AT6+AW6+AZ6+BC6+BF6+BI6+BL6+BO6 | AB6: 0 | AC6: =Z6-AD6-AE6-AB6 | AE6: 0
A7: SPM | B7: 15/2/2023 | C7: NA | D7: 2300040 | E7: SP0025 | F7: Label for Laparoscopic Trocar Disposable [5mm obturator*1+100mm sleeve*1] Model No.:FAS05100S | G7: SP2300040 | H7: NA | J7: NA | K7: February.-2023 | M7: February.-2026 | O7: NA | U7: 0 | V7: No. | Y7: Dispatched | Z7: =U7-W7 | AA7: =AC7+AH7+AK7+AN7+AQ7+AT7+AW7+AZ7+BC7+BF7+BI7+BL7+BO7 | AB7: 0 | AC7: =Z7-AD7-AE7-AB7 | AE7: 0
A8: SPM | B8: 15/2/2023 | C8: NA | D8: 2300041 | E8: SP0022 | F8: Label for Laparoscopic Trocar Disposable [5m obturator*1+100mm sleeve*1] Model No.:FAS05100V | G8: SP2300041 | H8: NA | J8: NA | K8: February.-2023 | M8: February.-2026 | O8: NA | U8: 0 | V8: No. | Y8: Dispatched | Z8: =U8-W8 | AA8: =AC8+AH8+AK8+AN8+AQ8+AT8+AW8+AZ8+BC8+BF8+BI8+BL8+BO8 | AB8: 0 | AC8: =Z8-AD8-AE8-AB8 | AE8: 0
A9: SPM | B9: 15/2/2023 | C9: NA | D9: 2300042 | E9: SP0021 | F9: Label for Laparoscopic Trocar Disposable [5mm obturator*1+150mm sleeve*1] Model No.:FAS05150N | G9: SP2300042 | H9: NA | J9: NA | K9: February.-2023 | M9: February.-2026 | O9: NA | U9: 0 | V9: No. | Y9: Dispatched | Z9: =U9-W9 | AA9: =AC9+AH9+AK9+AN9+AQ9+AT9+AW9+AZ9+BC9+BF9+BI9+BL9+BO9 | AB9: 0 | AC9: =Z9-AD9-AE9-AB9 | AE9: 0
A10: SPM | B10: 15/2/2023 | C10: NA | D10: 2300043 | E10: SP0023 | F10: Label for Laparoscopic Trocar Disposable [5mm obturator*1+150mm sleeve*1] Model No.:FAS05150V | G10: SP2300043 | H10: NA | J10: NA | K10: February.-2023 | M10: February.-2026 | O10: NA | U10: 0 | V10: No. | Y10: Dispatched | Z10: =U10-W10 | AA10: =AC10+AH10+AK10+AN10+AQ10+AT10+AW10+AZ10+BC10+BF10+BI10+BL10+BO10 | AB10: 0 | AC10: =Z10-AD10-AE10-AB10 | AE10: 0
A11: SPM | B11: 15/2/2023 | C11: NA | D11: 2300044 | E11: SP0015 | F11: Label for Laparoscopic Trocar Disposable [11mm obturator*1+100mm sleeve*1] Model No.:FAS11100D | G11: SP2300044 | H11: NA | J11: NA | K11: February.-2023 | M11: February.-2026 | O11: NA | U11: 0 | V11: No. | Y11: Dispatched | Z11: =U11-W11 | AA11: =AC11+AH11+AK11+AN11+AQ11+AT11+AW11+AZ11+BC11+BF11+BI11+BL11+BO11 | AB11: 0 | AC11: =Z11-AD11-AE11-AB11 | AE11: 0
A12: SPM | B12: 15/2/2023 | C12: NA | D12: 2300045 | E12: SP0018 | F12: Label for Laparoscopic Trocar Disposable [11mm obturator*1+100mm sleeve*1] Model No.:FAS11100H | G12: SP2300045 | H12: NA | J12: NA | K12: February.-2023 | M12: February.-2026 | O12: NA | U12: 0 | V12: No. | Y12: Dispatched | Z12: =U12-W12 | AA12: =AC12+AH12+AK12+AN12+AQ12+AT12+AW12+AZ12+BC12+BF12+BI12+BL12+BO12 | AB12: 0 | AC12: =Z12-AD12-AE12-AB12 | AE12: 0
A13: SPM | B13: 15/2/2023 | C13: NA | D13: 2300046 | E13: SP0033 | F13: Label for Laparoscopic Trocar Disposable [11mm obturator*1+100mm sleeve*1] Model No.:FAS11100P | G13: SP2300046 | H13: NA | J13: NA | K13: February.-2023 | M13: February.-2026 | O13: NA | U13: 0 | V13: No. | Y13: Dispatched | Z13: =U13-W13 | AA13: =AC13+AH13+AK13+AN13+AQ13+AT13+AW13+AZ13+BC13+BF13+BI13+BL13+BO13 | AB13: 0 | AC13: =Z13-AD13-AE13-AB13 | AE13: 0
A14: SPM | B14: 15/2/2023 | C14: NA | D14: 2300047 | E14: SP0019 | F14: Label for Laparoscopic Trocar Disposable [11mm obturator*1+100mm sleeve*1] Model No.:FAS11100S | G14: SP2300047 | H14: NA | J14: NA | K14: February.-2023 | M14: February.-2026 | O14: NA | U14: 0 | V14: No. | Y14: Dispatched | Z14: =U14-W14 | AA14: =AC14+AH14+AK14+AN14+AQ14+AT14+AW14+AZ14+BC14+BF14+BI14+BL14+BO14 | AB14: 0 | AC14: =Z14-AD14-AE14-AB14 | AE14: 0
